<?xml version="1.0" ?>

<robot name="blue_container" xmlns:xacro="http://www.ros.org/wiki/xacro">

<xacro:macro name="left_door">
 

  <link name="left_door_container_link">
    <inertial>
    <origin xyz="0 0 0.1125" rpy="0 0 0"/>
    <xacro:cylinder_inertia mass="1" r="0.05" l="0.225" />
    <mass value= "1"/>
    </inertial>

    <collision >
    <origin xyz="0 0 0" rpy="0 0 0"/>
    <geometry>
        <mesh filename="$(find forklift_simulator)/urdf/blue_container/meshes/blue_container_left_door_hc.dae" />
    </geometry>
    </collision>

    <visual >
    <origin xyz="0 0 0" rpy="0 0 0"/>
    <geometry>
        <mesh filename="$(find forklift_simulator)/urdf/blue_container/meshes/blue_container_left_door_hc.dae" />
    </geometry>
    </visual>
  </link>
    
  <joint name="left_door_container_joint" type="revolute">
    <parent link="base_link" />
    <child link="left_door_container_link" />
    <origin xyz="0.039 -1.2 0" rpy="0 0 0" />
    <axis xyz="0 0 1" />
    <limit lower="-3.14" upper="1.57" effort="30" velocity="0.3"/>
     <dynamics damping="1" friction="1"/>
  </joint>


  <transmission name="trans_left_door">
    <type>transmission_interface/SimpleTransmission</type>
    <joint name="left_door_container_joint">
      <hardwareInterface>hardware_interface/EffortJointInterface</hardwareInterface>
    </joint>
    <actuator name="motor_trans_left_door">
      <hardwareInterface>hardware_interface/EffortJointInterface</hardwareInterface>
      <mechanicalReduction>1</mechanicalReduction>
    </actuator>
  </transmission>

 </xacro:macro>

</robot>
