<?xml version="1.0" ?>

<robot name="EVX_14" xmlns:xacro="http://www.ros.org/wiki/xacro">

<xacro:macro name="evx_load_wheel" params="name x_loading y_loading z_loading radius width flip">

  <link name="wheel_${name}_driving_link">
    <inertial>
    <origin xyz="0 0 0" rpy="0 0 0"/>
    <xacro:cylinder_inertia mass="1" r="${radius}" l="${width}" />
    <mass value= "1"/>
    </inertial>

    <collision >
      <origin xyz="0 0 0" rpy="0 0 0"/>
      <geometry>
           <cylinder radius="${radius}" length="${width}"/>
           <!-- <mesh filename="$(find forklift_simulator)/urdf/EVX_14/meshes/EVX_14_load_wheel.dae" /> -->
      </geometry>
    </collision>

    <visual>
    <origin xyz="0 0 0" rpy="0 0 0"/>
    <geometry>
        <mesh filename="$(find forklift_simulator)/urdf/EVX_14/meshes/EVX_14_load_wheel.dae" />
    </geometry>
    </visual>
  </link>
    
  <joint name="wheel_${name}_driving_joint" type="continuous">
    <parent link="base_link" />
    <child link="wheel_${name}_driving_link" />
    <origin xyz="${x_loading} ${y_loading} ${z_loading}" rpy="1.57 0 0" />
    <axis xyz="0 0 ${1*flip}" />
    <joint_properties damping="1.0" friction="1.0"/>
  </joint>

  <gazebo reference="wheel_${name}_driving_link">
			<mu1>1</mu1>
			<mu2>1</mu2>
			<kp>1000000000.0</kp>
			<kd>1000.0</kd>
			<minDepth>0.001</minDepth>
			<maxVel>0</maxVel>		
		</gazebo>

 </xacro:macro>

</robot>
