<?xml version="1.0" ?>

<robot name="EVX_14" xmlns:xacro="http://www.ros.org/wiki/xacro">

 <link name="pris_link">
    <inertial>
    <origin xyz="0 0 0" rpy="0 0 0"/>
    <xacro:box_inertia mass="0.1" x="0.2" y="0.1" z="0.05"/>
    <mass value= "0.1"/>
    </inertial>

    <collision name="pris_collision">
    <origin xyz="0 0 0" rpy="0 0 0"/>
    <geometry> <mesh filename="$(find forklift_simulator)/urdf/EVX_14/meshes/EVX_14_load_fork.dae" />
    </geometry>
    
      <surface>
              <friction>
                <ode>
                  <mu>1.0</mu>
                  <mu2>1.0</mu2>
                  <fdir1>0.000000 0.000000 0.000000</fdir1>
                  <slip1>0.000000</slip1>
                  <slip2>0.000000</slip2>
                </ode>
              </friction>
              <bounce>
                <restitution_coefficient>0.0</restitution_coefficient>
                <threshold>100000.0</threshold>
              </bounce>
              <contact>
                <ode>
                  <soft_cfm>0.000000</soft_cfm>
                  <soft_erp>0.200000</soft_erp>
                  <kp>3000000000.000000</kp>
                  <kd>1.000000</kd>
                  <max_vel>0.010000</max_vel>
                  <min_depth>0.00000</min_depth>
                </ode>
              </contact>
      </surface>

    </collision>

    <visual name="pris_visual">
    <origin xyz="0 0 0" rpy="0 0 0"/>
    <geometry>
          <mesh filename="$(find forklift_simulator)/urdf/EVX_14/meshes/EVX_14_load_fork.dae" />
    </geometry>
    </visual>
  </link>
    
  <joint name="pris_joint" type="prismatic">
    <parent link="base_link" />
    <child link="pris_link" />
    <origin xyz="0 0 0.03" rpy="0 0 0" />
    <axis xyz="0 0 1" />
    <limit lower="0.05" upper="2" effort="100" velocity="0.3"/>
     <dynamics damping="100.0" friction="1"/>
  </joint>

  <transmission name="tran1">
    <type>transmission_interface/SimpleTransmission</type>
    <joint name="pris_joint">
      <hardwareInterface>hardware_interface/EffortJointInterface</hardwareInterface>
    </joint>
    <actuator name="motor1">
      <hardwareInterface>hardware_interface/EffortJointInterface</hardwareInterface>
      <mechanicalReduction>1</mechanicalReduction>
    </actuator>
  </transmission>

  <gazebo>
    <plugin name="gazebo_ros_control" filename="libgazebo_ros_control.so">
      <robotNamespace>/EVX_14</robotNamespace>
      <robotSimType>gazebo_ros_control/DefaultRobotHWSim</robotSimType>
    </plugin>
  </gazebo>

  <!-- <link name='box'>
    <collision>
      <geometry>
        <box size="1.2 0.8 0.1"/>
      </geometry>
    </collision>
    <visual>
      <geometry>
        <box size="1.2 0.8 0.1"/>
      </geometry>
    </visual>
  </link>

  <joint name="pad_joint" type="fixed">
    <parent link="pris_link" />
    <child link="box" />
    <origin xyz="0.7 0 0.06" rpy="0 0 0" />
    <axis xyz="0 0 1" />
  </joint> -->


  </robot>