<?xml version="1.0" ?>

<robot name="RX20_16" xmlns:xacro="http://www.ros.org/wiki/xacro">

<xacro:macro name="rx20_steer_wheel" params="name x_steering y_steering z_steering radius width flip">
 

  <link name="wheel_${name}_steering_link">
    <inertial>
    <origin xyz="0 0 0.1125" rpy="0 0 0"/>
    <xacro:cylinder_inertia mass="1" r="0.05" l="0.225" />
    <mass value= "1"/>
    </inertial>

    <collision >
    <origin xyz="0 0 0" rpy="0 0 0"/>
    <geometry>
        <mesh filename="$(find forklift_simulator)/urdf/RX20_16/meshes/steering_rod.dae" />
    </geometry>
    </collision>

    <visual >
    <origin xyz="0 0 0" rpy="0 0 0"/>
    <geometry>
        <mesh filename="$(find forklift_simulator)/urdf/RX20_16/meshes/steering_rod.dae" />
    </geometry>
    </visual>
  </link>
    
  <joint name="wheel_${name}_steering_joint" type="revolute">
    <parent link="base_link" />
    <child link="wheel_${name}_steering_link" />
    <origin xyz="${x_steering} ${y_steering} ${z_steering }" rpy="0 0 1.57" />
    <!-- <origin xyz="-0.662 0.247 0.115" rpy="0 0 0" /> -->
    <axis xyz="0 0 ${1*flip}" />
    <limit lower="-1.0" upper="1.0" effort="30" velocity="0.3"/>
     <dynamics damping="1" friction="1"/>
  </joint>

  <link name="wheel_${name}_link">
    <inertial>
    <origin xyz="0 0 0" rpy="0 0 0"/>
    <xacro:cylinder_inertia mass="0.5" r="${radius}" l="${width}" />
    <mass value= "0.5"/>
    </inertial>

    <collision >
      <origin xyz="0 0 0" rpy="0 0 0"/>
      <geometry>
           <cylinder radius="${radius}" length="${width}"/>
           <!-- <mesh filename="$(find forklift_simulator)/urdf/RX20_16/meshes/EVX_14_drive_wheel.dae" /> -->
      </geometry>
    </collision>

    <visual>
    <origin xyz="0 0 0" rpy="0 0 0"/>
    <geometry>
        <mesh filename="$(find forklift_simulator)/urdf/RX20_16/meshes/rear_wheel.dae" />
    </geometry>
    </visual>
  </link>
    
  <joint name="wheel_${name}_joint" type="continuous">
    <parent link="wheel_${name}_steering_link" />
    <child link="wheel_${name}_link" />
    <origin xyz=" 0 0 -0.09" rpy="0 1.57 0" />
    <axis xyz="0 0 1" />
    <!-- <joint_properties damping="1.0" friction="0.3"/> -->
        <limit effort="100" velocity="100"/>
     <dynamics damping="0.01" friction="0.0"/>
  </joint>

  <transmission name="trans_steering_${name}">
    <type>transmission_interface/SimpleTransmission</type>
    <joint name="wheel_${name}_steering_joint">
      <hardwareInterface>hardware_interface/EffortJointInterface</hardwareInterface>
    </joint>
    <actuator name="motor_steering_wheel_${name}">
      <hardwareInterface>hardware_interface/EffortJointInterface</hardwareInterface>
      <mechanicalReduction>1</mechanicalReduction>
    </actuator>
  </transmission>

  <!-- <transmission name="trans_dynamic_${name}">
    <type>transmission_interface/SimpleTransmission</type>
    <joint name="wheel_${name}_joint">
      <hardwareInterface>hardware_interface/EffortJointInterface</hardwareInterface>
    </joint>
    <actuator name="motor_dynamic_wheel_${name}">
      <hardwareInterface>hardware_interface/EffortJointInterface</hardwareInterface>
      <mechanicalReduction>1</mechanicalReduction>
    </actuator>
  </transmission> -->

  <gazebo reference="wheel_${name}_link">
			<mu1>1</mu1>
			<mu2>1</mu2>
			<!-- <kp>10000000.0</kp> -->
			<kp>1000000000.0</kp>
			<kd>1000.0</kd>
			<minDepth>0.002</minDepth>
			<maxVel>0</maxVel>		
		</gazebo>

 </xacro:macro>

</robot>
